<?xml version="1.0"?>
<robot xmlns:xacro="http://www.ros.org/wiki/xacro">

<!--Models-->
    <xacro:property name="base_path" value="file:////home/zega/Desktop/ros_dev/src/real/meshes/base1.dae" />
    <xacro:property name="arm_path_1" value="file:////home/zega/Desktop/ros_dev/src/real/meshes/l-1.dae" />
    <xacro:property name="arm_path_2" value="file:////home/zega/Desktop/ros_dev/src/real/meshes/l-2.dae" />
    <xacro:property name="arm_path_3" value="file:////home/zega/Desktop/ros_dev/src/real/meshes/l-3.dae" />
    <xacro:property name="camera" value="file:////home/zega/Desktop/ros_dev/src/real/meshes/kinect.dae" />
 <!--Models-->
    <material name="white">
        <color rgba="1 1 1 1" />
    </material>

    <material name="orange">
        <color rgba="1 0.3 0.1 1"/>
    </material>

    <material name="blue">
        <color rgba="0.2 0.2 1 1"/>
    </material>

    <material name="black">
        <color rgba="0 0 0 1"/>
    </material>

    <material name="red">
        <color rgba="1 0 0 1"/>
    </material>
<!--Phys macro-->
	<xacro:macro name="inertial_box" params="mass x y z *origin">
		<inertial>
			<xacro:insert_block name="origin"/>
			<mass value="${mass}" />
			<inertia ixx="${(1/12) * mass * (y*y+z*z)}" ixy="0.0" ixz="0.0"
                    iyy="${(1/12) * mass * (x*x+z*z)}" iyz="0.0"
                    izz="${(1/12) * mass * (x*x+y*y)}" />
		</inertial>
	</xacro:macro>

    <xacro:macro name="inertial_cylinder" params="mass length radius *origin">
        <inertial>
            <xacro:insert_block name="origin"/>
            <mass value="${mass}" />
            <inertia ixx="${(1/12) * mass * (3*radius*radius + length*length)}" ixy="0.0" ixz="0.0"
                    iyy="${(1/12) * mass * (3*radius*radius + length*length)}" iyz="0.0"
                    izz="${(1/2) * mass * (radius*radius)}" />
        </inertial>
    </xacro:macro>

<!--LEG MACROS-->
    <xacro:macro name="leg_section_joint" params="joint_name joint_axis joint_xyz joint_parent joint_child lower_limit upper_limit ">
		<joint name="${joint_name}" type="revolute">
		    <origin xyz="${joint_xyz}" />
		    <parent link="${joint_parent}" />
		    <child link="${joint_child}" />
		    <axis xyz="${joint_axis}"/>
		    <limit lower="${lower_limit}" upper="${upper_limit}"  velocity="50" effort="5"/>
            <dynamics damping="1.7" friction="1.7"/>
	    </joint>

    </xacro:macro>
    <xacro:macro name="leg_section_link" params="link_name link_xyz link_rpy model">
        <link name="${link_name}">
		    <visual>
			    <origin xyz="${link_xyz}" rpy="${link_rpy}"/>
			    <geometry>
			    	<mesh filename="${model}"/>
			    </geometry>
		    </visual>
		    <collision>
			    <origin xyz="${link_xyz}" rpy="${link_rpy}"/>
			    <geometry>
				    <mesh filename="${model}"/>
			    </geometry>
		    </collision>
		    <xacro:inertial_box mass="0.5" x="0.09" y="0.02" z="0.2">
			    <origin xyz="${link_xyz}" rpy="${link_rpy}"/>
		    </xacro:inertial_box>
	    </link>

	</xacro:macro>
    
</robot>
